<?xml version="1.0" encoding="utf-8"?>
<!-- This URDF was automatically created by SolidWorks to URDF Exporter! Originally created by Stephen Brawner (brawner@gmail.com) 
     Commit Version: 1.6.0-4-g7f85cfe  Build Version: 1.6.7995.38578
     For more information, please see http://wiki.ros.org/sw_urdf_exporter -->
<robot
  name="delto" xmlns:xacro="http://www.ros.org/wiki/xacro">
  <xacro:include filename="$(find delto)/urdf/delto.gazebo" />
  
  <link name="world"/>
  <joint name="base_joint"
    type="fixed">
    <origin
      xyz="0 0 0"
      rpy="0 0 0" />
    <parent
      link="world" />
    <child
      link="base_link" />
    <axis
      xyz="0 0 0" />
  </joint>
  <link
    name="base_link">
    <inertial>
      <origin
        xyz="0.0163977810461998 -0.000424816867342437 0.078525694814142"
        rpy="0 0 0" />
      <mass
        value="0.292" />
      <inertia
        ixx="0"
        ixy="0"
        ixz="0"
        iyy="0"
        iyz="0"
        izz="0" />
    </inertial>
    <visual>
      <origin
        xyz="0 0 0"
        rpy="0 0 0" />
      <geometry>
        <mesh
          filename="package://delto/meshes/base_link.STL" />
      </geometry>
      <material
        name="">
        <color
          rgba="0.792156862745098 0.819607843137255 0.933333333333333 1" />
      </material>
    </visual>
    <collision>
      <origin
        xyz="0 0 0"
        rpy="0 0 0" />
      <geometry>
        <mesh
          filename="package://delto/meshes/base_link.STL" />
      </geometry>
    </collision>
  </link>
  <link
    name="finger1_link1">
    <inertial>
      <origin
        xyz="0.0163977810461998 -0.000424816867342437 0.078525694814142"
        rpy="0 0 0" />
      <mass
        value="0.048" />
      <inertia
        ixx="0"
        ixy="0"
        ixz="0"
        iyy="0"
        iyz="0"
        izz="0" />
    </inertial>
    <visual>
      <origin
        xyz="0 0 0"
        rpy="0 0 0" />
      <geometry>
        <mesh
          filename="package://delto/meshes/finger1_link1.STL" />
      </geometry>
      <material
        name="">
        <color
          rgba="0.792156862745098 0.819607843137255 0.933333333333333 1" />
      </material>
    </visual>
    <collision>
      <origin
        xyz="0 0 0"
        rpy="0 0 0" />
      <geometry>
        <mesh
          filename="package://delto/meshes/finger1_link1.STL" />
      </geometry>
    </collision>
  </link>
  <joint
    name="finger1_joint1"
    type="revolute">
    <origin
      xyz="0.0150000000430074 0 0.0829999999999999"
      rpy="0 0 0" />
    <parent
      link="base_link" />
    <child
      link="finger1_link1" />
    <axis
      xyz="0 0 1" />
    <limit
      lower="-0.804"
      upper="0.804"
      effort="10"
      velocity="100" />
    <dynamics damping="0.64" friction="1"/>
  </joint>

  <transmission name="tran_1_1">
    <type>transmission_interface/SimpleTransmission</type>
    <joint name="finger1_joint1">
      <hardwareInterface>hardware_interface/EffortJointInterface</hardwareInterface>
    </joint>
    <actuator name="motor_1_1">
      <hardwareInterface>hardware_interface/EffortJointInterface</hardwareInterface>
      <mechanicalReduction>1</mechanicalReduction>
    </actuator>
  </transmission>

  <link
    name="finger1_link2">
    <inertial>
      <origin
        xyz="0.0163977810461998 -0.000424816867342437 0.078525694814142"
        rpy="0 0 0" />
      <mass
        value="0.012" />
      <inertia
        ixx="0"
        ixy="0"
        ixz="0"
        iyy="0"
        iyz="0"
        izz="0" />
    </inertial>
    <visual>
      <origin
        xyz="0 0 0"
        rpy="0 0 0" />
      <geometry>
        <mesh
          filename="package://delto/meshes/finger1_link2.STL" />
      </geometry>
      <material
        name="">
        <color
          rgba="0.792156862745098 0.819607843137255 0.933333333333333 1" />
      </material>
    </visual>
    <collision>
      <origin
        xyz="0 0 0"
        rpy="0 0 0" />
      <geometry>
        <mesh
          filename="package://delto/meshes/finger1_link2.STL" />
      </geometry>
    </collision>
  </link>
  <joint
    name="finger1_joint2"
    type="revolute">
    <origin
      xyz="0.0114 -5.8419E-05 0.0091"
      rpy="1.57 0 1.57" />
    <parent
      link="finger1_link1" />
    <child
      link="finger1_link2" />
    <axis
      xyz="0 0 1" />
    <limit
      lower="-1.714"
      upper="1.714"
      effort="10"
      velocity="100" />
    <dynamics damping="0.64" friction="1"/>
  </joint>

  <transmission name="tran_1_2">
    <type>transmission_interface/SimpleTransmission</type>
    <joint name="finger1_joint2">
      <hardwareInterface>hardware_interface/EffortJointInterface</hardwareInterface>
    </joint>
    <actuator name="motor_1_2">
      <hardwareInterface>hardware_interface/EffortJointInterface</hardwareInterface>
      <mechanicalReduction>1</mechanicalReduction>
    </actuator>
  </transmission>

  <link
    name="finger1_link3">
    <inertial>
      <origin
        xyz="0.0163977810461998 -0.000424816867342437 0.078525694814142"
        rpy="0 0 0" />
      <mass
        value="0.038" />
      <inertia
        ixx="0"
        ixy="0"
        ixz="0"
        iyy="0"
        iyz="0"
        izz="0" />
    </inertial>
    <visual>
      <origin
        xyz="0 0 0"
        rpy="0 0 0" />
      <geometry>
        <mesh
          filename="package://delto/meshes/finger1_link3.STL" />
      </geometry>
      <material
        name="">
        <color
          rgba="0.792156862745098 0.819607843137255 0.933333333333333 1" />
      </material>
    </visual>
    <collision>
      <origin
        xyz="0 0 0"
        rpy="0 0 0" />
      <geometry>
        <mesh
          filename="package://delto/meshes/finger1_link3.STL" />
      </geometry>
    </collision>
  </link>
  <joint
    name="finger1_joint3"
    type="revolute">
    <origin
      xyz="-0.014938 0.0098942 0.0203"
      rpy="1.57 -1.57 -1.57" />
    <parent
      link="finger1_link2" />
    <child
      link="finger1_link3" />
    <axis
      xyz="0 0 1" />
    <limit
      lower="0"
      upper="2.199"
      effort="10"
      velocity="100" />
    <dynamics damping="0.64" friction="1"/>
  </joint>

  <transmission name="tran_1_3">
    <type>transmission_interface/SimpleTransmission</type>
    <joint name="finger1_joint3">
      <hardwareInterface>hardware_interface/EffortJointInterface</hardwareInterface>
    </joint>
    <actuator name="motor_1_3">
      <hardwareInterface>hardware_interface/EffortJointInterface</hardwareInterface>
      <mechanicalReduction>1</mechanicalReduction>
    </actuator>
  </transmission>

  <link
    name="finger1_link4">
    <inertial>
      <origin
        xyz="0.0163977810461998 -0.000424816867342437 0.078525694814142"
        rpy="0 0 0" />
      <mass
        value="0.06" />
      <inertia
        ixx="0"
        ixy="0"
        ixz="0"
        iyy="0"
        iyz="0"
        izz="0" />
    </inertial>
    <visual>
      <origin
        xyz="0 0 0"
        rpy="0 0 0" />
      <geometry>
        <mesh
          filename="package://delto/meshes/finger1_link4.STL" />
      </geometry>
      <material
        name="">
        <color
          rgba="0.792156862745098 0.819607843137255 0.933333333333333 1" />
      </material>
    </visual>
    <collision>
      <origin
        xyz="0 0 0"
        rpy="0 0 0" />
      <geometry>
        <mesh
          filename="package://delto/meshes/finger1_link4.STL" />
      </geometry>
    </collision>
  </link>
  <joint
    name="finger1_joint4"
    type="revolute">
    <origin
      xyz="0.043312 -0.00012363 0"
      rpy="0 0 0" />
    <parent
      link="finger1_link3" />
    <child
      link="finger1_link4" />
    <axis
      xyz="0 0 1" />
    <limit
      lower="-0.376"
      upper="2.225"
      effort="10"
      velocity="100" />
    <dynamics damping="0.64" friction="1"/>
  </joint>

  <transmission name="tran_1_4">
    <type>transmission_interface/SimpleTransmission</type>
    <joint name="finger1_joint4">
      <hardwareInterface>hardware_interface/EffortJointInterface</hardwareInterface>
    </joint>
    <actuator name="motor_1_4">
      <hardwareInterface>hardware_interface/EffortJointInterface</hardwareInterface>
      <mechanicalReduction>1</mechanicalReduction>
    </actuator>
  </transmission>

  <link
    name="finger2_link1">
    <inertial>
      <origin
        xyz="0.0163977810461998 -0.000424816867342437 0.078525694814142"
        rpy="0 0 0" />
      <mass
        value="0.048" />
      <inertia
        ixx="0"
        ixy="0"
        ixz="0"
        iyy="0"
        iyz="0"
        izz="0" />
    </inertial>
    <visual>
      <origin
        xyz="0 0 0"
        rpy="0 0 0" />
      <geometry>
        <mesh
          filename="package://delto/meshes/finger2_link1.STL" />
      </geometry>
      <material
        name="">
        <color
          rgba="0.792156862745098 0.819607843137255 0.933333333333333 1" />
      </material>
    </visual>
    <collision>
      <origin
        xyz="0 0 0"
        rpy="0 0 0" />
      <geometry>
        <mesh
          filename="package://delto/meshes/finger2_link1.STL" />
      </geometry>
    </collision>
  </link>
  <joint
    name="finger2_joint1"
    type="revolute">
    <origin
      xyz="-0.0132 0.0196 0.083"
      rpy="0 0 3.14" />
    <parent
      link="base_link" />
    <child
      link="finger2_link1" />
    <axis
      xyz="0 0 1" />
    <limit
      lower="-2.147"
      upper="0.788"
      effort="10"
      velocity="100" />
    <dynamics damping="0.64" friction="1"/>
  </joint>

  <transmission name="tran_2_1">
    <type>transmission_interface/SimpleTransmission</type>
    <joint name="finger2_joint1">
      <hardwareInterface>hardware_interface/EffortJointInterface</hardwareInterface>
    </joint>
    <actuator name="motor_2_1">
      <hardwareInterface>hardware_interface/EffortJointInterface</hardwareInterface>
      <mechanicalReduction>1</mechanicalReduction>
    </actuator>
  </transmission>

  <link
    name="finger2_link2">
    <inertial>
      <origin
        xyz="0.0163977810461998 -0.000424816867342437 0.078525694814142"
        rpy="0 0 0" />
      <mass
        value="0.012" />
      <inertia
        ixx="0"
        ixy="0"
        ixz="0"
        iyy="0"
        iyz="0"
        izz="0" />
    </inertial>
    <visual>
      <origin
        xyz="0 0 0"
        rpy="0 0 0" />
      <geometry>
        <mesh
          filename="package://delto/meshes/finger2_link2.STL" />
      </geometry>
      <material
        name="">
        <color
          rgba="0.792156862745098 0.819607843137255 0.933333333333333 1" />
      </material>
    </visual>
    <collision>
      <origin
        xyz="0 0 0"
        rpy="0 0 0" />
      <geometry>
        <mesh
          filename="package://delto/meshes/finger2_link2.STL" />
      </geometry>
    </collision>
  </link>
  <joint
    name="finger2_joint2"
    type="revolute">
    <origin
      xyz="0.014198 -0.00024724 0.0091"
      rpy="0.0 -1.57 3.14" />
    <parent
      link="finger2_link1" />
    <child
      link="finger2_link2" />
    <axis
      xyz="0 0 1" />
    <limit
      lower="-1.714"
      upper="1.714"
      effort="10"
      velocity="100" />
    <dynamics damping="0.64" friction="1"/>
  </joint>
  
  <transmission name="tran_2_2">
    <type>transmission_interface/SimpleTransmission</type>
    <joint name="finger2_joint2">
      <hardwareInterface>hardware_interface/EffortJointInterface</hardwareInterface>
    </joint>
    <actuator name="motor_2_2">
      <hardwareInterface>hardware_interface/EffortJointInterface</hardwareInterface>
      <mechanicalReduction>1</mechanicalReduction>
    </actuator>
  </transmission>

  <link
    name="finger2_link3">
    <inertial>
      <origin
        xyz="0.0163977810461998 -0.000424816867342437 0.078525694814142"
        rpy="0 0 0" />
      <mass
        value="0.038" />
      <inertia
        ixx="0"
        ixy="0"
        ixz="0"
        iyy="0"
        iyz="0"
        izz="0" />
    </inertial>
    <visual>
      <origin
        xyz="0 0 0"
        rpy="0 0 0" />
      <geometry>
        <mesh
          filename="package://delto/meshes/finger2_link3.STL" />
      </geometry>
      <material
        name="">
        <color
          rgba="0.792156862745098 0.819607843137255 0.933333333333333 1" />
      </material>
    </visual>
    <collision>
      <origin
        xyz="0 0 0"
        rpy="0 0 0" />
      <geometry>
        <mesh
          filename="package://delto/meshes/finger2_link3.STL" />
      </geometry>
    </collision>
  </link>
  <joint
    name="finger2_joint3"
    type="revolute">
    <origin
      xyz="0.010098 0.014801 0.0175"
      rpy="-1.57 1.57 0.0" />
    <parent
      link="finger2_link2" />
    <child
      link="finger2_link3" />
    <axis
      xyz="0 0 1" />
    <limit
      lower="0"
      upper="2.199"
      effort="10"
      velocity="100" />
    <dynamics damping="0.64" friction="1"/>
  </joint>
  
  <transmission name="tran_2_3">
    <type>transmission_interface/SimpleTransmission</type>
    <joint name="finger2_joint3">
      <hardwareInterface>hardware_interface/EffortJointInterface</hardwareInterface>
    </joint>
    <actuator name="motor_2_3">
      <hardwareInterface>hardware_interface/EffortJointInterface</hardwareInterface>
      <mechanicalReduction>1</mechanicalReduction>
    </actuator>
  </transmission>

  <link
    name="finger2_link4">
    <inertial>
      <origin
        xyz="0.0163977810461998 -0.000424816867342437 0.078525694814142"
        rpy="0 0 0" />
      <mass
        value="0.06" />
      <inertia
        ixx="0"
        ixy="0"
        ixz="0"
        iyy="0"
        iyz="0"
        izz="0" />
    </inertial>
    <visual>
      <origin
        xyz="0 0 0"
        rpy="0 0 0" />
      <geometry>
        <mesh
          filename="package://delto/meshes/finger2_link4.STL" />
      </geometry>
      <material
        name="">
        <color
          rgba="0.792156862745098 0.819607843137255 0.933333333333333 1" />
      </material>
    </visual>
    <collision>
      <origin
        xyz="0 0 0"
        rpy="0 0 0" />
      <geometry>
        <mesh
          filename="package://delto/meshes/finger2_link4.STL" />
      </geometry>
    </collision>
  </link>
  <joint
    name="finger2_joint4"
    type="revolute">
    <origin
      xyz="-0.043282 0.0016118 0"
      rpy="0 0 0" />
    <parent
      link="finger2_link3" />
    <child
      link="finger2_link4" />
    <axis
      xyz="0 0 1" />
    <limit
      lower="-0.376"
      upper="2.225"
      effort="10"
      velocity="100" />
    <dynamics damping="0.64" friction="1"/>
  </joint>
  
  <transmission name="tran_2_4">
    <type>transmission_interface/SimpleTransmission</type>
    <joint name="finger2_joint4">
      <hardwareInterface>hardware_interface/EffortJointInterface</hardwareInterface>
    </joint>
    <actuator name="motor_2_4">
      <hardwareInterface>hardware_interface/EffortJointInterface</hardwareInterface>
      <mechanicalReduction>1</mechanicalReduction>
    </actuator>
  </transmission>

  <link
    name="finger3_link1">
    <inertial>
      <origin
        xyz="0.0163977810461998 -0.000424816867342437 0.078525694814142"
        rpy="0 0 0" />
      <mass
        value="0.048" />
      <inertia
        ixx="0"
        ixy="0"
        ixz="0"
        iyy="0"
        iyz="0"
        izz="0" />
    </inertial>
    <visual>
      <origin
        xyz="0 0 0"
        rpy="0 0 0" />
      <geometry>
        <mesh
          filename="package://delto/meshes/finger3_link1.STL" />
      </geometry>
      <material
        name="">
        <color
          rgba="0.792156862745098 0.819607843137255 0.933333333333333 1" />
      </material>
    </visual>
    <collision>
      <origin
        xyz="0 0 0"
        rpy="0 0 0" />
      <geometry>
        <mesh
          filename="package://delto/meshes/finger3_link1.STL" />
      </geometry>
    </collision>
  </link>
  <joint
    name="finger3_joint1"
    type="revolute">
    <origin
      xyz="-0.0131999999939963 -0.019600000000007 0.0829999999999988"
      rpy="0 0 3.14" />
    <parent
      link="base_link" />
    <child
      link="finger3_link1" />
    <axis
      xyz="0 0 1" />
    <limit
      lower="-0.788"
      upper="2.147"
      effort="10"
      velocity="100" />
    <dynamics damping="0.64" friction="1"/>
  </joint>
  
  <transmission name="tran_3_1">
    <type>transmission_interface/SimpleTransmission</type>
    <joint name="finger3_joint1">
      <hardwareInterface>hardware_interface/EffortJointInterface</hardwareInterface>
    </joint>
    <actuator name="motor_3_1">
      <hardwareInterface>hardware_interface/EffortJointInterface</hardwareInterface>
      <mechanicalReduction>1</mechanicalReduction>
    </actuator>
  </transmission>

  <link
    name="finger3_link2">
    <inertial>
      <origin
        xyz="0.0163977810461998 -0.000424816867342437 0.078525694814142"
        rpy="0 0 0" />
      <mass
        value="0.012" />
      <inertia
        ixx="0"
        ixy="0"
        ixz="0"
        iyy="0"
        iyz="0"
        izz="0" />
    </inertial>
    <visual>
      <origin
        xyz="0 0 0"
        rpy="0 0 0" />
      <geometry>
        <mesh
          filename="package://delto/meshes/finger3_link2.STL" />
      </geometry>
      <material
        name="">
        <color
          rgba="0.792156862745098 0.819607843137255 0.933333333333333 1" />
      </material>
    </visual>
    <collision>
      <origin
        xyz="0 0 0"
        rpy="0 0 0" />
      <geometry>
        <mesh
          filename="package://delto/meshes/finger3_link2.STL" />
      </geometry>
    </collision>
  </link>
  <joint
    name="finger3_joint2"
    type="revolute">
    <origin
      xyz="0.0141973935884402 -0.000272057521322411 0.00910000000000048"
      rpy="3.14 -1.57 0" />
    <parent
      link="finger3_link1" />
    <child
      link="finger3_link2" />
    <axis
      xyz="0 0 1" />
    <limit
      lower="-1.714"
      upper="1.714"
      effort="10"
      velocity="100" />
    <dynamics damping="0.64" friction="1"/>
  </joint>
  
  <transmission name="tran_3_2">
    <type>transmission_interface/SimpleTransmission</type>
    <joint name="finger3_joint2">
      <hardwareInterface>hardware_interface/EffortJointInterface</hardwareInterface>
    </joint>
    <actuator name="motor_3_2">
      <hardwareInterface>hardware_interface/EffortJointInterface</hardwareInterface>
      <mechanicalReduction>1</mechanicalReduction>
    </actuator>
  </transmission>

  <link
    name="finger3_link3">
    <inertial>
      <origin
        xyz="0.0163977810461998 -0.000424816867342437 0.078525694814142"
        rpy="0 0 0" />
      <mass
        value="0.038" />
      <inertia
        ixx="0"
        ixy="0"
        ixz="0"
        iyy="0"
        iyz="0"
        izz="0" />
    </inertial>
    <visual>
      <origin
        xyz="0 0 0"
        rpy="0 0 0" />
      <geometry>
        <mesh
          filename="package://delto/meshes/finger3_link3.STL" />
      </geometry>
      <material
        name="">
        <color
          rgba="0.792156862745098 0.819607843137255 0.933333333333333 1" />
      </material>
    </visual>
    <collision>
      <origin
        xyz="0 0 0"
        rpy="0 0 0" />
      <geometry>
        <mesh
          filename="package://delto/meshes/finger3_link3.STL" />
      </geometry>
    </collision>
  </link>
  <joint
    name="finger3_joint3"
    type="revolute">
    <origin
      xyz="0.01025 0.014696 0.0175"
      rpy="1.57 1.57 3.14" />
    <parent
      link="finger3_link2" />
    <child
      link="finger3_link3" />
    <axis
      xyz="0 0 1" />
    <limit
      lower="0"
      upper="2.199"
      effort="10"
      velocity="100" />
    <dynamics damping="0.64" friction="1"/>
  </joint>
  
  <transmission name="tran_3_3">
    <type>transmission_interface/SimpleTransmission</type>
    <joint name="finger3_joint3">
      <hardwareInterface>hardware_interface/EffortJointInterface</hardwareInterface>
    </joint>
    <actuator name="motor_3_3">
      <hardwareInterface>hardware_interface/EffortJointInterface</hardwareInterface>
      <mechanicalReduction>1</mechanicalReduction>
    </actuator>
  </transmission>

  <link
    name="finger3_link4">
    <inertial>
      <origin
        xyz="0.0163977810461998 -0.000424816867342437 0.078525694814142"
        rpy="0 0 0" />
      <mass
        value="0.06" />
      <inertia
        ixx="0"
        ixy="0"
        ixz="0"
        iyy="0"
        iyz="0"
        izz="0" />
    </inertial>
    <visual>
      <origin
        xyz="0 0 0"
        rpy="0 0 0" />
      <geometry>
        <mesh
          filename="package://delto/meshes/finger3_link4.STL" />
      </geometry>
      <material
        name="">
        <color
          rgba="0.792156862745098 0.819607843137255 0.933333333333333 1" />
      </material>
    </visual>
    <collision>
      <origin
        xyz="0 0 0"
        rpy="0 0 0" />
      <geometry>
        <mesh
          filename="package://delto/meshes/finger3_link4.STL" />
      </geometry>
    </collision>
  </link>
  <joint
    name="finger3_joint4"
    type="revolute">
    <origin
      xyz="-0.043308 -0.0006013 0"
      rpy="0 0 0" />
    <parent
      link="finger3_link3" />
    <child
      link="finger3_link4" />
    <axis
      xyz="0 0 1" />
    <limit
      lower="-0.376"
      upper="2.225"
      effort="10"
      velocity="100" />
    <dynamics damping="0.64" friction="1"/>
  </joint>
  
  <transmission name="tran_3_4">
    <type>transmission_interface/SimpleTransmission</type>
    <joint name="finger3_joint4">
      <hardwareInterface>hardware_interface/EffortJointInterface</hardwareInterface>
    </joint>
    <actuator name="motor_3_4">
      <hardwareInterface>hardware_interface/EffortJointInterface</hardwareInterface>
      <mechanicalReduction>1</mechanicalReduction>
    </actuator>
  </transmission>

</robot>